{"channel":"l2_data","timestamp":"2026-05-04T12:00:00.050Z","sequence_num":1,"events":[{"type":"snapshot","product_id":"BTC-USD","updates":[{"side":"bid","event_time":"2026-05-04T12:00:00.050Z","price_level":"67499.50","new_quantity":"2.0156"},{"side":"bid","event_time":"2026-05-04T12:00:00.050Z","price_level":"67499.00","new_quantity":"0.5640"},{"side":"bid","event_time":"2026-05-04T12:00:00.050Z","price_level":"67498.50","new_quantity":"0.7538"},{"side":"bid","event_time":"2026-05-04T12:00:00.050Z","price_level":"67498.00","new_quantity":"1.2018"},{"side":"bid","event_time":"2026-05-04T12:00:00.050Z","price_level":"67497.50","new_quantity":"1.6058"},{"side":"bid","event_time":"2026-05-04T12:00:00.050Z","price_level":"67497.00","new_quantity":"1.1447"},{"side":"bid","event_time":"2026-05-04T12:00:00.050Z","price_level":"67496.50","new_quantity":"0.4705"},{"side":"bid","event_time":"2026-05-04T12:00:00.050Z","price_level":"67496.00","new_quantity":"0.2256"},{"side":"bid","event_time":"2026-05-04T12:00:00.050Z","price_level":"67495.50","new_quantity":"0.5654"},{"side":"bid","event_time":"2026-05-04T12:00:00.050Z","price_level":"67495.00","new_quantity":"0.7283"},{"side":"offer","event_time":"2026-05-04T12:00:00.050Z","price_level":"67500.50","new_quantity":"2.0780"},{"side":"offer","event_time":"2026-05-04T12:00:00.050Z","price_level":"67501.00","new_quantity":"1.7296"},{"side":"offer","event_time":"2026-05-04T12:00:00.050Z","price_level":"67501.50","new_quantity":"1.5594"},{"side":"offer","event_time":"2026-05-04T12:00:00.050Z","price_level":"67502.00","new_quantity":"0.5729"},{"side":"offer","event_time":"2026-05-04T12:00:00.050Z","price_level":"67502.50","new_quantity":"1.7273"},{"side":"offer","event_time":"2026-05-04T12:00:00.050Z","price_level":"67503.00","new_quantity":"1.6418"},{"side":"offer","event_time":"2026-05-04T12:00:00.050Z","price_level":"67503.50","new_quantity":"1.2935"},{"side":"offer","event_time":"2026-05-04T12:00:00.050Z","price_level":"67504.00","new_quantity":"0.8564"},{"side":"offer","event_time":"2026-05-04T12:00:00.050Z","price_level":"67504.50","new_quantity":"1.3173"},{"side":"offer","event_time":"2026-05-04T12:00:00.050Z","price_level":"67505.00","new_quantity":"1.3413"}]}]}
{"channel":"l2_data","timestamp":"2026-05-04T12:00:00.100Z","sequence_num":2,"events":[{"type":"snapshot","product_id":"ETH-USD","updates":[{"side":"bid","event_time":"2026-05-04T12:00:00.100Z","price_level":"3499.50","new_quantity":"0.6123"},{"side":"bid","event_time":"2026-05-04T12:00:00.100Z","price_level":"3499.00","new_quantity":"1.4951"},{"side":"bid","event_time":"2026-05-04T12:00:00.100Z","price_level":"3498.50","new_quantity":"0.7362"},{"side":"bid","event_time":"2026-05-04T12:00:00.100Z","price_level":"3498.00","new_quantity":"0.9030"},{"side":"bid","event_time":"2026-05-04T12:00:00.100Z","price_level":"3497.50","new_quantity":"1.7447"},{"side":"bid","event_time":"2026-05-04T12:00:00.100Z","price_level":"3497.00","new_quantity":"1.1620"},{"side":"bid","event_time":"2026-05-04T12:00:00.100Z","price_level":"3496.50","new_quantity":"0.3300"},{"side":"bid","event_time":"2026-05-04T12:00:00.100Z","price_level":"3496.00","new_quantity":"1.3391"},{"side":"bid","event_time":"2026-05-04T12:00:00.100Z","price_level":"3495.50","new_quantity":"1.9874"},{"side":"bid","event_time":"2026-05-04T12:00:00.100Z","price_level":"3495.00","new_quantity":"0.5437"},{"side":"offer","event_time":"2026-05-04T12:00:00.100Z","price_level":"3500.50","new_quantity":"1.1784"},{"side":"offer","event_time":"2026-05-04T12:00:00.100Z","price_level":"3501.00","new_quantity":"1.7314"},{"side":"offer","event_time":"2026-05-04T12:00:00.100Z","price_level":"3501.50","new_quantity":"1.6094"},{"side":"offer","event_time":"2026-05-04T12:00:00.100Z","price_level":"3502.00","new_quantity":"1.0860"},{"side":"offer","event_time":"2026-05-04T12:00:00.100Z","price_level":"3502.50","new_quantity":"0.4529"},{"side":"offer","event_time":"2026-05-04T12:00:00.100Z","price_level":"3503.00","new_quantity":"1.9452"},{"side":"offer","event_time":"2026-05-04T12:00:00.100Z","price_level":"3503.50","new_quantity":"0.1101"},{"side":"offer","event_time":"2026-05-04T12:00:00.100Z","price_level":"3504.00","new_quantity":"1.6011"},{"side":"offer","event_time":"2026-05-04T12:00:00.100Z","price_level":"3504.50","new_quantity":"0.7300"},{"side":"offer","event_time":"2026-05-04T12:00:00.100Z","price_level":"3505.00","new_quantity":"1.7443"}]}]}
{"channel":"l2_data","timestamp":"2026-05-04T12:00:00.360Z","sequence_num":3,"events":[{"type":"update","product_id":"BTC-USD","updates":[{"side":"bid","event_time":"2026-05-04T12:00:00.360Z","price_level":"67505.35","new_quantity":"1.3485"},{"side":"bid","event_time":"2026-05-04T12:00:00.360Z","price_level":"67508.37","new_quantity":"1.4557"},{"side":"offer","event_time":"2026-05-04T12:00:00.360Z","price_level":"67509.56","new_quantity":"0.5819"}]}]}
{"channel":"heartbeats","timestamp":"2026-05-04T12:00:00.460Z","sequence_num":4,"events":[{"current_time":"2026-05-04T12:00:00.460Z","heartbeat_counter":1}]}
{"channel":"l2_data","timestamp":"2026-05-04T12:00:00.770Z","sequence_num":5,"events":[{"type":"update","product_id":"ETH-USD","updates":[{"side":"bid","event_time":"2026-05-04T12:00:00.770Z","price_level":"3500.62","new_quantity":"2.0996"},{"side":"bid","event_time":"2026-05-04T12:00:00.770Z","price_level":"3498.26","new_quantity":"0.6340"},{"side":"offer","event_time":"2026-05-04T12:00:00.770Z","price_level":"3504.48","new_quantity":"1.0700"}]}]}
{"channel":"heartbeats","timestamp":"2026-05-04T12:00:00.870Z","sequence_num":6,"events":[{"current_time":"2026-05-04T12:00:00.870Z","heartbeat_counter":2}]}
{"channel":"l2_data","timestamp":"2026-05-04T12:00:01.071Z","sequence_num":7,"events":[{"type":"update","product_id":"BTC-USD","updates":[{"side":"offer","event_time":"2026-05-04T12:00:01.071Z","price_level":"67510.15","new_quantity":"0.0000"}]}]}
{"channel":"l2_data","timestamp":"2026-05-04T12:00:01.354Z","sequence_num":8,"events":[{"type":"update","product_id":"ETH-USD","updates":[{"side":"bid","event_time":"2026-05-04T12:00:01.354Z","price_level":"3495.93","new_quantity":"1.6634"},{"side":"bid","event_time":"2026-05-04T12:00:01.354Z","price_level":"3496.18","new_quantity":"0.2002"},{"side":"offer","event_time":"2026-05-04T12:00:01.354Z","price_level":"3502.78","new_quantity":"0.2912"}]}]}
{"channel":"l2_data","timestamp":"2026-05-04T12:00:01.823Z","sequence_num":9,"events":[{"type":"update","product_id":"BTC-USD","updates":[{"side":"offer","event_time":"2026-05-04T12:00:01.823Z","price_level":"67503.15","new_quantity":"0.8581"},{"side":"bid","event_time":"2026-05-04T12:00:01.823Z","price_level":"67494.33","new_quantity":"0.9887"},{"side":"bid","event_time":"2026-05-04T12:00:01.823Z","price_level":"67498.22","new_quantity":"1.8475"}]}]}
{"channel":"l2_data","timestamp":"2026-05-04T12:00:02.159Z","sequence_num":10,"events":[{"type":"update","product_id":"ETH-USD","updates":[{"side":"offer","event_time":"2026-05-04T12:00:02.159Z","price_level":"3499.42","new_quantity":"0.0000"}]}]}
{"channel":"l2_data","timestamp":"2026-05-04T12:00:02.447Z","sequence_num":11,"events":[{"type":"update","product_id":"BTC-USD","updates":[{"side":"offer","event_time":"2026-05-04T12:00:02.447Z","price_level":"67498.89","new_quantity":"0.0000"}]}]}
{"channel":"l2_data","timestamp":"2026-05-04T12:00:02.897Z","sequence_num":12,"events":[{"type":"update","product_id":"ETH-USD","updates":[{"side":"offer","event_time":"2026-05-04T12:00:02.897Z","price_level":"3499.06","new_quantity":"0.6149"}]}]}
{"channel":"l2_data","timestamp":"2026-05-04T12:00:03.098Z","sequence_num":13,"events":[{"type":"update","product_id":"BTC-USD","updates":[{"side":"bid","event_time":"2026-05-04T12:00:03.098Z","price_level":"67505.51","new_quantity":"2.0175"},{"side":"bid","event_time":"2026-05-04T12:00:03.098Z","price_level":"67505.02","new_quantity":"1.5845"}]}]}
{"channel":"heartbeats","timestamp":"2026-05-04T12:00:03.198Z","sequence_num":14,"events":[{"current_time":"2026-05-04T12:00:03.198Z","heartbeat_counter":3}]}
{"channel":"l2_data","timestamp":"2026-05-04T12:00:03.418Z","sequence_num":15,"events":[{"type":"update","product_id":"ETH-USD","updates":[{"side":"offer","event_time":"2026-05-04T12:00:03.418Z","price_level":"3502.52","new_quantity":"0.0000"}]}]}
{"channel":"l2_data","timestamp":"2026-05-04T12:00:03.698Z","sequence_num":16,"events":[{"type":"update","product_id":"BTC-USD","updates":[{"side":"offer","event_time":"2026-05-04T12:00:03.698Z","price_level":"67510.81","new_quantity":"0.0000"},{"side":"bid","event_time":"2026-05-04T12:00:03.698Z","price_level":"67503.60","new_quantity":"0.3310"}]}]}
{"channel":"l2_data","timestamp":"2026-05-04T12:00:04.077Z","sequence_num":17,"events":[{"type":"update","product_id":"ETH-USD","updates":[{"side":"bid","event_time":"2026-05-04T12:00:04.077Z","price_level":"3498.13","new_quantity":"1.2575"},{"side":"bid","event_time":"2026-05-04T12:00:04.077Z","price_level":"3497.18","new_quantity":"0.1891"},{"side":"bid","event_time":"2026-05-04T12:00:04.077Z","price_level":"3499.97","new_quantity":"1.7328"}]}]}
{"channel":"heartbeats","timestamp":"2026-05-04T12:00:04.177Z","sequence_num":18,"events":[{"current_time":"2026-05-04T12:00:04.177Z","heartbeat_counter":4}]}
{"channel":"l2_data","timestamp":"2026-05-04T12:00:04.663Z","sequence_num":19,"events":[{"type":"update","product_id":"BTC-USD","updates":[{"side":"offer","event_time":"2026-05-04T12:00:04.663Z","price_level":"67503.50","new_quantity":"1.2317"},{"side":"offer","event_time":"2026-05-04T12:00:04.663Z","price_level":"67501.81","new_quantity":"1.8662"},{"side":"bid","event_time":"2026-05-04T12:00:04.663Z","price_level":"67497.27","new_quantity":"0.0000"}]}]}
{"channel":"l2_data","timestamp":"2026-05-04T12:00:04.954Z","sequence_num":20,"events":[{"type":"update","product_id":"ETH-USD","updates":[{"side":"bid","event_time":"2026-05-04T12:00:04.954Z","price_level":"3493.72","new_quantity":"1.5400"},{"side":"bid","event_time":"2026-05-04T12:00:04.954Z","price_level":"3494.87","new_quantity":"1.9745"},{"side":"offer","event_time":"2026-05-04T12:00:04.954Z","price_level":"3501.55","new_quantity":"2.0332"}]}]}
{"channel":"l2_data","timestamp":"2026-05-04T12:00:05.171Z","sequence_num":21,"events":[{"type":"update","product_id":"BTC-USD","updates":[{"side":"bid","event_time":"2026-05-04T12:00:05.171Z","price_level":"67496.94","new_quantity":"0.6913"},{"side":"offer","event_time":"2026-05-04T12:00:05.171Z","price_level":"67500.99","new_quantity":"0.7877"},{"side":"offer","event_time":"2026-05-04T12:00:05.171Z","price_level":"67500.91","new_quantity":"0.7729"}]}]}
{"channel":"l2_data","timestamp":"2026-05-04T12:00:05.468Z","sequence_num":22,"events":[{"type":"update","product_id":"ETH-USD","updates":[{"side":"bid","event_time":"2026-05-04T12:00:05.468Z","price_level":"3495.63","new_quantity":"1.4490"},{"side":"offer","event_time":"2026-05-04T12:00:05.468Z","price_level":"3499.34","new_quantity":"1.7528"}]}]}
{"channel":"l2_data","timestamp":"2026-05-04T12:00:05.801Z","sequence_num":23,"events":[{"type":"update","product_id":"BTC-USD","updates":[{"side":"bid","event_time":"2026-05-04T12:00:05.801Z","price_level":"67487.77","new_quantity":"1.7946"},{"side":"offer","event_time":"2026-05-04T12:00:05.801Z","price_level":"67492.25","new_quantity":"1.7960"}]}]}
{"channel":"heartbeats","timestamp":"2026-05-04T12:00:05.901Z","sequence_num":24,"events":[{"current_time":"2026-05-04T12:00:05.901Z","heartbeat_counter":5}]}
{"channel":"l2_data","timestamp":"2026-05-04T12:00:06.370Z","sequence_num":25,"events":[{"type":"update","product_id":"ETH-USD","updates":[{"side":"bid","event_time":"2026-05-04T12:00:06.370Z","price_level":"3497.76","new_quantity":"1.6762"}]}]}
{"channel":"l2_data","timestamp":"2026-05-04T12:00:06.718Z","sequence_num":26,"events":[{"type":"update","product_id":"BTC-USD","updates":[{"side":"bid","event_time":"2026-05-04T12:00:06.718Z","price_level":"67499.59","new_quantity":"0.6748"}]}]}
{"channel":"l2_data","timestamp":"2026-05-04T12:00:07.022Z","sequence_num":27,"events":[{"type":"update","product_id":"ETH-USD","updates":[{"side":"offer","event_time":"2026-05-04T12:00:07.022Z","price_level":"3503.03","new_quantity":"1.7216"},{"side":"offer","event_time":"2026-05-04T12:00:07.022Z","price_level":"3504.74","new_quantity":"1.5970"},{"side":"bid","event_time":"2026-05-04T12:00:07.022Z","price_level":"3496.19","new_quantity":"0.7829"}]}]}
{"channel":"l2_data","timestamp":"2026-05-04T12:00:07.302Z","sequence_num":28,"events":[{"type":"update","product_id":"BTC-USD","updates":[{"side":"offer","event_time":"2026-05-04T12:00:07.302Z","price_level":"67508.57","new_quantity":"0.2731"}]}]}
{"channel":"l2_data","timestamp":"2026-05-04T12:00:07.748Z","sequence_num":29,"events":[{"type":"update","product_id":"ETH-USD","updates":[{"side":"bid","event_time":"2026-05-04T12:00:07.748Z","price_level":"3499.84","new_quantity":"0.1460"},{"side":"offer","event_time":"2026-05-04T12:00:07.748Z","price_level":"3501.14","new_quantity":"0.9604"},{"side":"offer","event_time":"2026-05-04T12:00:07.748Z","price_level":"3504.28","new_quantity":"1.6556"}]}]}
{"channel":"heartbeats","timestamp":"2026-05-04T12:00:07.848Z","sequence_num":30,"events":[{"current_time":"2026-05-04T12:00:07.848Z","heartbeat_counter":6}]}
{"channel":"l2_data","timestamp":"2026-05-04T12:00:08.276Z","sequence_num":31,"events":[{"type":"update","product_id":"BTC-USD","updates":[{"side":"bid","event_time":"2026-05-04T12:00:08.276Z","price_level":"67499.72","new_quantity":"0.0000"}]}]}
{"channel":"l2_data","timestamp":"2026-05-04T12:00:08.695Z","sequence_num":32,"events":[{"type":"update","product_id":"ETH-USD","updates":[{"side":"offer","event_time":"2026-05-04T12:00:08.695Z","price_level":"3498.54","new_quantity":"0.0000"},{"side":"offer","event_time":"2026-05-04T12:00:08.695Z","price_level":"3500.74","new_quantity":"0.6685"},{"side":"bid","event_time":"2026-05-04T12:00:08.695Z","price_level":"3494.25","new_quantity":"1.2441"}]}]}
{"channel":"l2_data","timestamp":"2026-05-04T12:00:09.182Z","sequence_num":33,"events":[{"type":"update","product_id":"BTC-USD","updates":[{"side":"offer","event_time":"2026-05-04T12:00:09.182Z","price_level":"67495.30","new_quantity":"2.0365"}]}]}
{"channel":"heartbeats","timestamp":"2026-05-04T12:00:09.282Z","sequence_num":34,"events":[{"current_time":"2026-05-04T12:00:09.282Z","heartbeat_counter":7}]}
{"channel":"l2_data","timestamp":"2026-05-04T12:00:09.543Z","sequence_num":35,"events":[{"type":"update","product_id":"ETH-USD","updates":[{"side":"offer","event_time":"2026-05-04T12:00:09.543Z","price_level":"3502.77","new_quantity":"0.4782"},{"side":"offer","event_time":"2026-05-04T12:00:09.543Z","price_level":"3506.35","new_quantity":"1.5951"}]}]}
{"channel":"l2_data","timestamp":"2026-05-04T12:00:09.744Z","sequence_num":36,"events":[{"type":"update","product_id":"BTC-USD","updates":[{"side":"offer","event_time":"2026-05-04T12:00:09.744Z","price_level":"67501.04","new_quantity":"0.7121"},{"side":"offer","event_time":"2026-05-04T12:00:09.744Z","price_level":"67501.91","new_quantity":"1.7411"}]}]}
{"channel":"l2_data","timestamp":"2026-05-04T12:00:10.147Z","sequence_num":37,"events":[{"type":"update","product_id":"ETH-USD","updates":[{"side":"offer","event_time":"2026-05-04T12:00:10.147Z","price_level":"3504.73","new_quantity":"0.0000"},{"side":"offer","event_time":"2026-05-04T12:00:10.147Z","price_level":"3502.22","new_quantity":"0.8421"},{"side":"bid","event_time":"2026-05-04T12:00:10.147Z","price_level":"3497.40","new_quantity":"1.3287"}]}]}
{"channel":"l2_data","timestamp":"2026-05-04T12:00:10.585Z","sequence_num":38,"events":[{"type":"update","product_id":"BTC-USD","updates":[{"side":"bid","event_time":"2026-05-04T12:00:10.585Z","price_level":"67494.83","new_quantity":"0.2996"}]}]}
{"channel":"l2_data","timestamp":"2026-05-04T12:00:10.930Z","sequence_num":39,"events":[{"type":"update","product_id":"ETH-USD","updates":[{"side":"bid","event_time":"2026-05-04T12:00:10.930Z","price_level":"3498.08","new_quantity":"1.5283"},{"side":"offer","event_time":"2026-05-04T12:00:10.930Z","price_level":"3500.17","new_quantity":"0.2276"}]}]}
{"channel":"l2_data","timestamp":"2026-05-04T12:00:11.175Z","sequence_num":40,"events":[{"type":"update","product_id":"BTC-USD","updates":[{"side":"bid","event_time":"2026-05-04T12:00:11.175Z","price_level":"67506.60","new_quantity":"0.5336"},{"side":"bid","event_time":"2026-05-04T12:00:11.175Z","price_level":"67504.02","new_quantity":"0.0000"},{"side":"offer","event_time":"2026-05-04T12:00:11.175Z","price_level":"67512.01","new_quantity":"2.0235"}]}]}
{"channel":"l2_data","timestamp":"2026-05-04T12:00:11.652Z","sequence_num":41,"events":[{"type":"update","product_id":"ETH-USD","updates":[{"side":"offer","event_time":"2026-05-04T12:00:11.652Z","price_level":"3501.05","new_quantity":"2.0257"},{"side":"bid","event_time":"2026-05-04T12:00:11.652Z","price_level":"3498.19","new_quantity":"1.8672"},{"side":"bid","event_time":"2026-05-04T12:00:11.652Z","price_level":"3499.74","new_quantity":"0.4122"}]}]}
{"channel":"heartbeats","timestamp":"2026-05-04T12:00:11.752Z","sequence_num":42,"events":[{"current_time":"2026-05-04T12:00:11.752Z","heartbeat_counter":8}]}
{"channel":"l2_data","timestamp":"2026-05-04T12:00:12.239Z","sequence_num":43,"events":[{"type":"update","product_id":"BTC-USD","updates":[{"side":"offer","event_time":"2026-05-04T12:00:12.239Z","price_level":"67506.21","new_quantity":"1.4296"}]}]}
{"channel":"heartbeats","timestamp":"2026-05-04T12:00:12.339Z","sequence_num":44,"events":[{"current_time":"2026-05-04T12:00:12.339Z","heartbeat_counter":9}]}
{"channel":"l2_data","timestamp":"2026-05-04T12:00:12.581Z","sequence_num":45,"events":[{"type":"update","product_id":"ETH-USD","updates":[{"side":"offer","event_time":"2026-05-04T12:00:12.581Z","price_level":"3500.78","new_quantity":"0.3664"},{"side":"offer","event_time":"2026-05-04T12:00:12.581Z","price_level":"3501.93","new_quantity":"1.8221"}]}]}
{"channel":"l2_data","timestamp":"2026-05-04T12:00:12.831Z","sequence_num":46,"events":[{"type":"update","product_id":"BTC-USD","updates":[{"side":"offer","event_time":"2026-05-04T12:00:12.831Z","price_level":"67507.04","new_quantity":"1.3929"}]}]}
{"channel":"l2_data","timestamp":"2026-05-04T12:00:13.243Z","sequence_num":47,"events":[{"type":"update","product_id":"ETH-USD","updates":[{"side":"bid","event_time":"2026-05-04T12:00:13.243Z","price_level":"3496.12","new_quantity":"1.5401"}]}]}
{"channel":"l2_data","timestamp":"2026-05-04T12:00:13.469Z","sequence_num":48,"events":[{"type":"update","product_id":"BTC-USD","updates":[{"side":"offer","event_time":"2026-05-04T12:00:13.469Z","price_level":"67497.31","new_quantity":"1.9505"},{"side":"bid","event_time":"2026-05-04T12:00:13.469Z","price_level":"67492.04","new_quantity":"0.8399"},{"side":"bid","event_time":"2026-05-04T12:00:13.469Z","price_level":"67490.25","new_quantity":"1.4161"}]}]}
{"channel":"l2_data","timestamp":"2026-05-04T12:00:13.847Z","sequence_num":49,"events":[{"type":"update","product_id":"ETH-USD","updates":[{"side":"bid","event_time":"2026-05-04T12:00:13.847Z","price_level":"3497.80","new_quantity":"0.0000"},{"side":"bid","event_time":"2026-05-04T12:00:13.847Z","price_level":"3501.13","new_quantity":"1.4349"},{"side":"offer","event_time":"2026-05-04T12:00:13.847Z","price_level":"3505.87","new_quantity":"1.2648"}]}]}
{"channel":"l2_data","timestamp":"2026-05-04T12:00:14.146Z","sequence_num":50,"events":[{"type":"update","product_id":"BTC-USD","updates":[{"side":"bid","event_time":"2026-05-04T12:00:14.146Z","price_level":"67492.69","new_quantity":"1.2464"}]}]}
{"channel":"l2_data","timestamp":"2026-05-04T12:00:14.438Z","sequence_num":51,"events":[{"type":"update","product_id":"ETH-USD","updates":[{"side":"bid","event_time":"2026-05-04T12:00:14.438Z","price_level":"3501.64","new_quantity":"0.9901"},{"side":"offer","event_time":"2026-05-04T12:00:14.438Z","price_level":"3502.46","new_quantity":"0.6290"}]}]}
{"channel":"l2_data","timestamp":"2026-05-04T12:00:14.777Z","sequence_num":52,"events":[{"type":"update","product_id":"BTC-USD","updates":[{"side":"offer","event_time":"2026-05-04T12:00:14.777Z","price_level":"67497.57","new_quantity":"1.6421"},{"side":"offer","event_time":"2026-05-04T12:00:14.777Z","price_level":"67499.00","new_quantity":"1.5985"},{"side":"offer","event_time":"2026-05-04T12:00:14.777Z","price_level":"67497.57","new_quantity":"0.0000"}]}]}
{"channel":"heartbeats","timestamp":"2026-05-04T12:00:14.877Z","sequence_num":53,"events":[{"current_time":"2026-05-04T12:00:14.877Z","heartbeat_counter":10}]}
{"channel":"l2_data","timestamp":"2026-05-04T12:00:15.154Z","sequence_num":54,"events":[{"type":"update","product_id":"ETH-USD","updates":[{"side":"offer","event_time":"2026-05-04T12:00:15.154Z","price_level":"3503.96","new_quantity":"0.0000"}]}]}
{"channel":"heartbeats","timestamp":"2026-05-04T12:00:15.254Z","sequence_num":55,"events":[{"current_time":"2026-05-04T12:00:15.254Z","heartbeat_counter":11}]}
{"channel":"l2_data","timestamp":"2026-05-04T12:00:15.710Z","sequence_num":56,"events":[{"type":"update","product_id":"BTC-USD","updates":[{"side":"bid","event_time":"2026-05-04T12:00:15.710Z","price_level":"67500.26","new_quantity":"0.1688"},{"side":"bid","event_time":"2026-05-04T12:00:15.710Z","price_level":"67503.37","new_quantity":"0.1301"},{"side":"offer","event_time":"2026-05-04T12:00:15.710Z","price_level":"67505.59","new_quantity":"0.7244"}]}]}
{"channel":"l2_data","timestamp":"2026-05-04T12:00:16.077Z","sequence_num":57,"events":[{"type":"update","product_id":"ETH-USD","updates":[{"side":"bid","event_time":"2026-05-04T12:00:16.077Z","price_level":"3497.08","new_quantity":"0.8667"},{"side":"bid","event_time":"2026-05-04T12:00:16.077Z","price_level":"3499.91","new_quantity":"0.7665"}]}]}
{"channel":"l2_data","timestamp":"2026-05-04T12:00:16.488Z","sequence_num":58,"events":[{"type":"update","product_id":"BTC-USD","updates":[{"side":"offer","event_time":"2026-05-04T12:00:16.488Z","price_level":"67501.34","new_quantity":"0.6168"},{"side":"bid","event_time":"2026-05-04T12:00:16.488Z","price_level":"67495.83","new_quantity":"1.7871"}]}]}
{"channel":"l2_data","timestamp":"2026-05-04T12:00:16.751Z","sequence_num":59,"events":[{"type":"update","product_id":"ETH-USD","updates":[{"side":"offer","event_time":"2026-05-04T12:00:16.751Z","price_level":"3504.18","new_quantity":"1.7424"},{"side":"bid","event_time":"2026-05-04T12:00:16.751Z","price_level":"3498.91","new_quantity":"1.7085"}]}]}
{"channel":"l2_data","timestamp":"2026-05-04T12:00:17.210Z","sequence_num":60,"events":[{"type":"update","product_id":"BTC-USD","updates":[{"side":"bid","event_time":"2026-05-04T12:00:17.210Z","price_level":"67498.57","new_quantity":"0.9939"},{"side":"bid","event_time":"2026-05-04T12:00:17.210Z","price_level":"67499.61","new_quantity":"0.5854"}]}]}
{"channel":"l2_data","timestamp":"2026-05-04T12:00:17.454Z","sequence_num":61,"events":[{"type":"update","product_id":"ETH-USD","updates":[{"side":"offer","event_time":"2026-05-04T12:00:17.454Z","price_level":"3502.68","new_quantity":"0.3786"}]}]}
{"channel":"l2_data","timestamp":"2026-05-04T12:00:17.698Z","sequence_num":62,"events":[{"type":"update","product_id":"BTC-USD","updates":[{"side":"offer","event_time":"2026-05-04T12:00:17.698Z","price_level":"67510.55","new_quantity":"0.9889"},{"side":"bid","event_time":"2026-05-04T12:00:17.698Z","price_level":"67504.97","new_quantity":"0.5860"},{"side":"offer","event_time":"2026-05-04T12:00:17.698Z","price_level":"67510.22","new_quantity":"0.9614"}]}]}
{"channel":"heartbeats","timestamp":"2026-05-04T12:00:17.798Z","sequence_num":63,"events":[{"current_time":"2026-05-04T12:00:17.798Z","heartbeat_counter":12}]}
{"channel":"l2_data","timestamp":"2026-05-04T12:00:18.206Z","sequence_num":64,"events":[{"type":"update","product_id":"ETH-USD","updates":[{"side":"bid","event_time":"2026-05-04T12:00:18.206Z","price_level":"3496.35","new_quantity":"1.3444"},{"side":"bid","event_time":"2026-05-04T12:00:18.206Z","price_level":"3497.65","new_quantity":"2.0988"}]}]}
